{"timestamp": "2025-09-27T19:15:00.604012", "prompt": "Pick and place the cube", "scene_summary": {"objects": [{"name": "cube", "position": [0.5, 0.0, 0.1], "graspable": true}], "workspace": {"x_min": -1, "x_max": 1, "y_min": -1, "y_max": 1, "z_min": 0, "z_max": 2}}, "error": "Simulated GPT API connection error", "error_type": "ConnectionError", "traceback": "Traceback (most recent call last):\n  File \"C:\\Users/Dhenenjay/cogniforge\\cogniforge\\core\\expert_script_with_fallback.py\", line 118, in generate_expert_trajectory\n    trajectory = self._generate_with_gpt(prompt, scene_summary)\n                 ^^^^^^^^^^^^^^^^^^^^^^^^^^^^^^^^^^^^^^^^^^^^^^\n  File \"C:\\Users/Dhenenjay/cogniforge\\cogniforge\\core\\expert_script_with_fallback.py\", line 173, in _generate_with_gpt\n    response = self._call_gpt_api(codex_prompt)\n               ^^^^^^^^^^^^^^^^^^^^^^^^^^^^^^^^\n  File \"C:\\Users/Dhenenjay/cogniforge\\cogniforge\\core\\expert_script_with_fallback.py\", line 210, in _call_gpt_api\n    raise ConnectionError(\"Simulated GPT API connection error\")\nConnectionError: Simulated GPT API connection error\n", "attempt": 1}
